<mujoco model="hopper">
    <compiler angle="degree" coordinate="local"/>
    <!-- <option timestep="0.001"/> -->
    <option gravity="0 0 -9.81" timestep="0.0001"/>

    <default>
        <geom type="box" rgba="0.8 0.4 0.4 1"/>
        <joint damping="0.01"/>
        <motor ctrlrange="-1 1"/>
    </default>
    <worldbody>
        <light name="top" pos="0 0 1"/>
        <geom name="floor" type="plane" size="1 1 0.1" rgba="0.2 0.3 0.4 1"/>

        <body name="hopper" pos="0 0 0.05">
            <freejoint/>
            <inertial pos="0 0 0" mass="0.00095" diaginertia="6.0e-08 6.0e-08 7.5e-08"/>

            <geom name="hopper-torso" type="box" size="0.015 0.015 0.005" mass="0.00095"/>
            <body name="hopper-leg" pos="0 0 -0.03">
                <joint name="hopper-slide" type="slide" axis="0 0 1" pos="0 0 0" damping="0.01" stiffness="70" springref="0"/>
                <geom name="leg" type="capsule" fromto="0 0 0 0 0 -0.03" size="0.002" mass="0.00003"/>
            </body>
        </body>
    </worldbody>

    <actuator> 
        <motor name="thrust" joint="hopper-slide" gear="0 0 1 0 0 0" ctrlrange="0 0.0145"/>
    </actuator>

    <!-- <equality> -->
        <!-- <joint name="hopper-spring" joint="hopper-slide" stiffness="70"/> -->
    <!-- </equality> -->
</mujoco>