<mujoco model="hopper">
    <worldbody>
        <geom name="floor" type="plane" size="1 1 0.1" rgba="0.2 0.3 0.4 1"/>

        <body name="hopper">
            <geom name="hopper-body" type="box" size="0.015 0.015 0.005" mass="0.00095"/>
            <joint name="hopper-slide" type="slide" axis="0 0 1" pos="0 0 0"/>
            <geom name="hopper-leg" type="capsule" fromto="0 0 0 0 0 -0.03" size="0.002" mass="0.00003"/>
        <body/>
    <worldbody/>


    <actuator> 
        <motor name="thrust" joint="hopper-slide" gear="1" ctrlrange="0 0.0145"/>
    <actuator/>

    <equality>
        <joint name="hopper-spring" joint="hopper-slide" stiffness="70"/>
    <equality/>
<mujoco/>